<?xml version='1.0'?>

<robot name="udacity_bot" xmlns:xacro="http://www.ros.org/wiki/xacro">
  <xacro:include filename="$(find udacity_bot)/urdf/my_udacity_bot.gazebo" />
  
  <link name="robot_footprint"></link>

  <joint name="robot_footprint_joint" type="fixed">
    <origin xyz="0 0 0" rpy="0 0 0" />
    <parent link="robot_footprint"/>
    <child link="chassis" />
  </joint>

  <link name='chassis'>
    <pose>0 0 0.1 0 0 0</pose>

    <inertial>
      <mass value="15.0"/>
      <origin xyz="0.0 0 0" rpy=" 0 0 0"/>
      <inertia
          ixx="0.1" ixy="0" ixz="0"
          iyy="0.1" iyz="0"
          izz="0.1"
      />
    </inertial>

    <collision name='chassis_collision'>
      <origin xyz="-.05 0 0" rpy=" 0 0 0"/> 
      <geometry>
        <box size=".3 .2 .09"/>
      </geometry>
    </collision>

    <visual name='chassis_visual'>
      <origin xyz="-.05 0 0" rpy=" 0 0 0"/>
      <geometry>
        <box size=".3 .2 .09"/>
      </geometry>
    </visual>
    
    <collision name='back_chassis_collision'>
      <origin xyz="-.1 0 .045" rpy=" 0 0 0"/>
      <geometry>
        <box size=".19 .09 .11"/>
      </geometry>
    </collision>
    
    <visual name='back_chassis_visual'>
      <origin xyz="-.1 0 .045" rpy=" 0 0 0"/>
      <geometry>
        <box size=".2 .1 .12"/>
      </geometry>
    </visual>
    
    <visual name='wing_visual'>
      <origin xyz="-.22 0 0.12" rpy="0 0.3 0"/>
      <geometry>
        <box size=".1 .25 .015"/>
      </geometry>
    </visual>
    
    <collision name='wing_collision'>
      <origin xyz="-.22 0 0.12" rpy="0 0.3 0"/>
      <geometry>
        <box size=".09 .24 .014"/>
      </geometry>
    </collision>
    
    <collision name='front_chassis_collision'>
      <origin xyz=".18 0 -.01" rpy=" 0 0 0"/>
      <geometry>
        <box size=".21 .12 .07"/>
      </geometry>
    </collision>
    
    <visual name='front_chassis_visual'>
      <origin xyz=".18 0 -.01" rpy=" 0 0 0"/>
      <geometry>
        <box size=".22 .13 .08"/>
      </geometry>
    </visual>
    
    <visual name='bumper_visual'>
      <origin xyz=".3 0 -.03" rpy=" 0 0 0"/>
      <geometry>
        <box size=".1 .25 .03"/>
      </geometry>
    </visual>
    
    <collision name='bumper_collision'>
      <origin xyz=".3 0 -.03" rpy=" 0 0 0"/>
      <geometry>
        <box size=".09 .24 .02"/>
      </geometry>
    </collision>

	<!--////////////////////////////// CASTER //////////////////////////////-->
    <collision name='back_caster_collision'>
      <origin xyz="-0.15 0 -0.05" rpy=" 0 0 0"/>
      <geometry>
        <sphere radius="0.049"/>
      </geometry>
    </collision>

    <visual name='back_caster_visual'>
      <origin xyz="-0.15 0 -0.05" rpy=" 0 0 0"/>
      <geometry>
        <sphere radius="0.05"/>
      </geometry>
    </visual>

    <collision name='front_caster_collision'>
      <origin xyz="0.15 0 -0.05" rpy=" 0 0 0"/>
      <geometry>
        <sphere radius="0.049"/>
      </geometry>
    </collision>

    <visual name='front_caster_visual'>
      <origin xyz="0.15 0 -0.05" rpy=" 0 0 0"/>
      <geometry>
        <sphere radius="0.05"/>
      </geometry>
    </visual>

  </link>
  
  <!--////////////////////////////// WHEELS //////////////////////////////-->
  <link name='left_wheel'>
  	<inertial>
      <mass value="5.0"/>        
      <origin xyz="0 0 0" rpy="0 1.5705 1.5707"/>
      <inertia
        ixx="0.1" ixy="0" ixz="0"
        iyy="0.1" iyz="0"
        izz="0.1"
      />
    </inertial>
    
    <visual name='left_wheel_visual'>
      <origin xyz="0 0 0" rpy="0 1.5707 1.5707"/>
      <geometry>
        <cylinder radius="0.1" length="0.05"/>
      </geometry>
    </visual>
    
    <collision name='left_wheel_collision'>
      <origin xyz="0 0 0" rpy="0 1.5705 1.5707"/>
      <geometry>
        <cylinder radius="0.1" length="0.05"/>
      </geometry>
    </collision>
  </link>
  
  <link name='right_wheel'>
  	<inertial>
      <mass value="5.0"/>        
      <origin xyz="0 0 0" rpy="0 1.5705 1.5707"/>
      <inertia
        ixx="0.1" ixy="0" ixz="0"
        iyy="0.1" iyz="0"
        izz="0.1"
      />
    </inertial>

    <visual name='right_wheel_visual'>
      <origin xyz="0 0 0" rpy="0 1.5707 1.5707"/>
      <geometry>
        <cylinder radius="0.1" length="0.05"/>
      </geometry>
    </visual>
        
    <collision name='right_wheel_collision'>
      <origin xyz="0 0 0" rpy="0 1.5705 1.5707"/>
      <geometry>
      	<cylinder radius="0.1" length="0.05"/>
      </geometry>
    </collision>
  </link>
  
  <joint type="continuous" name="left_wheel_hinge">
    <origin xyz="0 0.15 0" rpy="0 0 0"/>
    <child link="left_wheel"/>
    <parent link="chassis"/>
    <axis xyz="0 1 0" rpy="0 0 0"/>
    <limit effort="10000" velocity="1000"/>
    <dynamics damping="1.0" friction="1.0"/>
  </joint>
  
  <joint type="continuous" name="right_wheel_hinge">
    <origin xyz="0 -0.15 0" rpy="0 0 0"/>
    <child link="right_wheel"/>
    <parent link="chassis"/>
    <axis xyz="0 1 0" rpy="0 0 0"/>
    <limit effort="10000" velocity="1000"/>
    <dynamics damping="1.0" friction="1.0"/>
  </joint>
  
  <!--////////////////////////////// CAMERA //////////////////////////////-->
  <link name='camera'>
    <inertial>
      <mass value="0.1"/>
      <origin xyz="0 0 0" rpy="0 0 0"/>
      <inertia
        ixx="1e-6" ixy="0" ixz="0"
        iyy="1e-6" iyz="0"
        izz="1e-6"
      />
    </inertial>
    
    <visual name='camera_visual'>
      <origin xyz="0 0 0" rpy="0 0 0"/>
      <geometry>
        <box size="0.05 0.05 0.05"/>
      </geometry>
    </visual>
    
    <collision name='camera_collision'>
      <origin xyz="0 0 0" rpy="0 0 0"/>
      <geometry>
        <box size="0.05 0.05 0.05"/>
      </geometry>
    </collision>
  </link>
  
  <joint type='fixed' name='camera_joint'>
    <origin xyz="0.315 0 0.01" rpy="0 0 0"/>
    <child link="camera"/>
    <parent link="chassis"/>
  </joint>
  
  <!--////////////////////////////// LASER RANGEFINDER //////////////////////////////-->
  <link name='hokuyo'>
    <inertial>
      <mass value="0.1"/>
      <origin xyz="0 0 0" rpy="0 0 0"/>
      <inertia 
         ixx="1e-6" ixy="0" ixz="0" 
         iyy="1e-6" iyz="0" 
         izz="1e-6"
       />
    </inertial>
    
    <visual name='hokuyo_visual'>
      <origin xyz="0 0 0" rpy="0 0 0"/>
      <geometry>
        <mesh filename="package://udacity_bot/meshes/hokuyo.dae"/>
      </geometry>
    </visual>
    
    <collision name='hokuyo_collision'>
      <origin xyz="0 0 0" rpy="0 0 0"/>
      <geometry>
        <box size="0.1 0.1 0.1"/>
      </geometry>
    </collision>
  </link>
  
  <joint type='fixed' name='hokuyo_joint'>
    <origin xyz="0.25 0 0.06" rpy="0 0 0"/>
    <!-- 0.25 0 0.15-->
    <child link="hokuyo"/>
    <parent link="chassis"/>
  </joint>
  
</robot>